Workbook

Sheet Base_Clientes
A1: ID_Cliente | B1: Nome_Cliente | C1: Cidade | D1: UF | E1: Idade | F1: Segmento | G1: Canal_Aquisicao | H1: Plano_ID | I1: Nome_Plano_PROCX | J1: Valor_Plano_PROCV | K1: Data_Entrada | L1: Mes_Entrada | M1: Status | N1: Data_Cancelamento | O1: Tempo_Cliente_Dias | P1: Faixa_Tempo_Cliente | Q1: Churn | R1: NPS | S1: Receita_Perdida | T1: Classificacao_NPS | U1: Risco_Churn | V1: Atrasos_Pagamento | W1: Uso_30d | X1: Mensalidade_Paga | Y1: Tempo_Cliente_Meses | Z1: Risco_Churn2
A2: C0001 | B2: Valentina Souza | C2: São Paulo | D2: SP | E2: 65 | F2: Pessoa Física | G2: LinkedIn | H2: P001 | I2: =_xludf.XLOOKUP(H2,Base_Planos!$A:$A,Base_Planos!$B:$B,"Não encontrado") -> #NAME? | J2: =VLOOKUP(H2,Base_Planos!$A:$G,4,FALSE) -> 39.9 | K2: 45136 | L2: 2023-07 | M2: Cancelado | N2: 45261 | O2: =IF(M2="Cancelado",N2-K2,TODAY()-K2) -> 125 | P2: =IF(O2<=30,"Até 30 dias",IF(O2<=90,"31 a 90 dias",IF(O2<=180,"91 a 180 dias",IF(O2<=365,"181 a 365 dias","Mais de 1 ano")))) -> 91 a 180 dias | Q2: =IF(M2="Cancelado",1,0) -> 1 | R2: 10 | S2: =IF(Q2=1,J2,0) -> 39.9 | T2: =IF(R2<=6,"Detrator",IF(R2<=8,"Neutro","Promotor")) -> Promotor | U2: =IF(Q2=1,"Alto risco",IF(R2<=6,"Alto risco",IF(R2<=8,"Médio risco","Baixo risco"))) -> Alto risco | V2: 1 | W2: 21 | X2: 35.77 | Y2: 4 | Z2: Médio
A3: C0002 | B3: Thiago Silva | C3: Goiânia | D3: GO | E3: 30 | F3: Pequena Empresa | G3: Parceiro | H3: P002 | I3: =_xludf.XLOOKUP(H3,Base_Planos!$A:$A,Base_Planos!$B:$B,"Não encontrado") -> #NAME? | J3: =VLOOKUP(H3,Base_Planos!$A:$G,4,FALSE) -> 29.9 | K3: 46133 | L3: 2026-04 | M3: Ativo | O3: =IF(M3="Cancelado",N3-K3,TODAY()-K3) -> 36 | P3: =IF(O3<=30,"Até 30 dias",IF(O3<=90,"31 a 90 dias",IF(O3<=180,"91 a 180 dias",IF(O3<=365,"181 a 365 dias","Mais de 1 ano")))) -> 31 a 90 dias | Q3: =IF(M3="Cancelado",1,0) -> 0 | R3: 4 | S3: =IF(Q3=1,J3,0) -> 0 | T3: =IF(R3<=6,"Detrator",IF(R3<=8,"Neutro","Promotor")) -> Detrator | U3: =IF(Q3=1,"Alto risco",IF(R3<=6,"Alto risco",IF(R3<=8,"Médio risco","Baixo risco"))) -> Alto risco | V3: 2 | W3: 54 | X3: 27.45 | Y3: 1 | Z3: Alto
A4: C0003 | B4: Eduarda Costa | C4: Santo André | D4: SP | E4: 39 | F4: Pessoa Física | G4: Parceiro | H4: P001 | I4: =_xludf.XLOOKUP(H4,Base_Planos!$A:$A,Base_Planos!$B:$B,"Não encontrado") -> #NAME? | J4: =VLOOKUP(H4,Base_Planos!$A:$G,4,FALSE) -> 39.9 | K4: 45631 | L4: 2024-12 | M4: Cancelado | N4: 46133 | O4: =IF(M4="Cancelado",N4-K4,TODAY()-K4) -> 502 | P4: =IF(O4<=30,"Até 30 dias",IF(O4<=90,"31 a 90 dias",IF(O4<=180,"91 a 180 dias",IF(O4<=365,"181 a 365 dias","Mais de 1 ano")))) -> Mais de 1 ano | Q4: =IF(M4="Cancelado",1,0) -> 1 | R4: 9 | S4: =IF(Q4=1,J4,0) -> 39.9 | T4: =IF(R4<=6,"Detrator",IF(R4<=8,"Neutro","Promotor")) -> Promotor | U4: =IF(Q4=1,"Alto risco",IF(R4<=6,"Alto risco",IF(R4<=8,"Médio risco","Baixo risco"))) -> Alto risco | V4: 0 | W4: 65 | X4: 34.54 | Y4: 16 | Z4: Baixo
A5: C0004 | B5: João Nascimento | C5: Guarulhos | D5: SP | E5: 41 | F5: MEI | G5: Instagram | H5: P001 | I5: =_xludf.XLOOKUP(H5,Base_Planos!$A:$A,Base_Planos!$B:$B,"Não encontrado") -> #NAME? | J5: =VLOOKUP(H5,Base_Planos!$A:$G,4,FALSE) -> 39.9 | K5: 45393 | L5: 2024-04 | M5: Cancelado | N5: 45887 | O5: =IF(M5="Cancelado",N5-K5,TODAY()-K5) -> 494 | P5: =IF(O5<=30,"Até 30 dias",IF(O5<=90,"31 a 90 dias",IF(O5<=180,"91 a 180 dias",IF(O5<=365,"181 a 365 dias","Mais de 1 ano")))) -> Mais de 1 ano | Q5: =IF(M5="Cancelado",1,0) -> 1 | R5: 4 | S5: =IF(Q5=1,J5,0) -> 39.9 | T5: =IF(R5<=6,"Detrator",IF(R5<=8,"Neutro","Promotor")) -> Detrator | U5: =IF(Q5=1,"Alto risco",IF(R5<=6,"Alto risco",IF(R5<=8,"Médio risco","Baixo risco"))) -> Alto risco | V5: 2 | W5: 51 | X5: 36.83 | Y5: 16 | Z5: Alto
A6: C0005 | B6: Lucas Martins | C6: Curitiba | D6: PR | E6: 60 | F6: Pessoa Física | G6: Instagram | H6: P004 | I6: =_xludf.XLOOKUP(H6,Base_Planos!$A:$A,Base_Planos!$B:$B,"Não encontrado") -> #NAME? | J6: =VLOOKUP(H6,Base_Planos!$A:$G,4,FALSE) -> 59.9 | K6: 45277 | L6: 2023-12 | M6: Ativo | O6: =IF(M6="Cancelado",N6-K6,TODAY()-K6) -> 892 | P6: =IF(O6<=30,"Até 30 dias",IF(O6<=90,"31 a 90 dias",IF(O6<=180,"91 a 180 dias",IF(O6<=365,"181 a 365 dias","Mais de 1 ano")))) -> Mais de 1 ano | Q6: =IF(M6="Cancelado",1,0) -> 0 | R6: 8 | S6: =IF(Q6=1,J6,0) -> 0 | T6: =IF(R6<=6,"Detrator",IF(R6<=8,"Neutro","Promotor")) -> Neutro | U6: =IF(Q6=1,"Alto risco",IF(R6<=6,"Alto risco",IF(R6<=8,"Médio risco","Baixo risco"))) -> Médio risco | V6: 0 | W6: 40 | X6: 58.58 | Y6: 29 | Z6: Baixo
A7: C0006 | B7: Rafael Ferreira | C7: Osasco | D7: SP | E7: 38 | F7: Média Empresa | G7: Google Ads | H7: P002 | I7: =_xludf.XLOOKUP(H7,Base_Planos!$A:$A,Base_Planos!$B:$B,"Não encontrado") -> #NAME? | J7: =VLOOKUP(H7,Base_Planos!$A:$G,4,FALSE) -> 29.9 | K7: 44992 | L7: 2023-03 | M7: Ativo | O7: =IF(M7="Cancelado",N7-K7,TODAY()-K7) -> 1177 | P7: =IF(O7<=30,"Até 30 dias",IF(O7<=90,"31 a 90 dias",IF(O7<=180,"91 a 180 dias",IF(O7<=365,"181 a 365 dias","Mais de 1 ano")))) -> Mais de 1 ano | Q7: =IF(M7="Cancelado",1,0) -> 0 | R7: 5 | S7: =IF(Q7=1,J7,0) -> 0 | T7: =IF(R7<=6,"Detrator",IF(R7<=8,"Neutro","Promotor")) -> Detrator | U7: =IF(Q7=1,"Alto risco",IF(R7<=6,"Alto risco",IF(R7<=8,"Médio risco","Baixo risco"))) -> Alto risco | V7: 3 | W7: 63 | X7: 29.71 | Y7: 39 | Z7: Médio
A8: C0007 | B8: Gabriela Barbosa | C8: Salvador | D8: BA | E8: 59 | F8: MEI | G8: Orgânico | H8: P001 | I8: =_xludf.XLOOKUP(H8,Base_Planos!$A:$A,Base_Planos!$B:$B,"Não encontrado") -> #NAME? | J8: =VLOOKUP(H8,Base_Planos!$A:$G,4,FALSE) -> 39.9 | K8: 46076 | L8: 2026-02 | M8: Ativo | O8: =IF(M8="Cancelado",N8-K8,TODAY()-K8) -> 93 | P8: =IF(O8<=30,"Até 30 dias",IF(O8<=90,"31 a 90 dias",IF(O8<=180,"91 a 180 dias",IF(O8<=365,"181 a 365 dias","Mais de 1 ano")))) -> 91 a 180 dias | Q8: =IF(M8="Cancelado",1,0) -> 0 | R8: 8 | S8: =IF(Q8=1,J8,0) -> 0 | T8: =IF(R8<=6,"Detrator",IF(R8<=8,"Neutro","Promotor")) -> Neutro | U8: =IF(Q8=1,"Alto risco",IF(R8<=6,"Alto risco",IF(R8<=8,"Médio risco","Baixo risco"))) -> Médio risco | V8: 2 | W8: 93 | X8: 35.67 | Y8: 3 | Z8: Baixo
A9: C0008 | B9: Eduarda Rocha | C9: Fortaleza | D9: CE | E9: 23 | F9: Pequena Empresa | G9: Instagram | H9: P001 | I9: =_xludf.XLOOKUP(H9,Base_Planos!$A:$A,Base_Planos!$B:$B,"Não encontrado") -> #NAME? | J9: =VLOOKUP(H9,Base_Planos!$A:$G,4,FALSE) -> 39.9 | K9: 45254 | L9: 2023-11 | M9: Ativo | O9: =IF(M9="Cancelado",N9-K9,TODAY()-K9) -> 915 | P9: =IF(O9<=30,"Até 30 dias",IF(O9<=90,"31 a 90 dias",IF(O9<=180,"91 a 180 dias",IF(O9<=365,"181 a 365 dias","Mais de 1 ano")))) -> Mais de 1 ano | Q9: =IF(M9="Cancelado",1,0) -> 0 | R9: 10 | S9: =IF(Q9=1,J9,0) -> 0 | T9: =IF(R9<=6,"Detrator",IF(R9<=8,"Neutro","Promotor")) -> Promotor | U9: =IF(Q9=1,"Alto risco",IF(R9<=6,"Alto risco",IF(R9<=8,"Médio risco","Baixo risco"))) -> Baixo risco | V9: 0 | W9: 61 | X9: 38.14 | Y9: 30 | Z9: Baixo
A10: C0009 | B10: Rafael Silva | C10: Osasco | D10: SP | E10: 64 | F10: Pessoa Física | G10: Orgânico | H10: P005 | I10: =_xludf.XLOOKUP(H10,Base_Planos!$A:$A,Base_Planos!$B:$B,"Não encontrado") -> #NAME? | J10: =VLOOKUP(H10,Base_Planos!$A:$G,4,FALSE) -> 149.9 | K10: 45623 | L10: 2024-11 | M10: Ativo | O10: =IF(M10="Cancelado",N10-K10,TODAY()-K10) -> 546 | P10: =IF(O10<=30,"Até 30 dias",IF(O10<=90,"31 a 90 dias",IF(O10<=180,"91 a 180 dias",IF(O10<=365,"181 a 365 dias","Mais de 1 ano")))) -> Mais de 1 ano | Q10: =IF(M10="Cancelado",1,0) -> 0 | R10: 1 | S10: =IF(Q10=1,J10,0) -> 0 | T10: =IF(R10<=6,"Detrator",IF(R10<=8,"Neutro","Promotor")) -> Detrator | U10: =IF(Q10=1,"Alto risco",IF(R10<=6,"Alto risco",IF(R10<=8,"Médio risco","Baixo risco"))) -> Alto risco | V10: 0 | W10: 72 | X10: 148.99 | Y10: 18 | Z10: Médio
A11: C0010 | B11: Queila Lima | C11: Goiânia | D11: GO | E11: 24 | F11: Média Empresa | G11: Orgânico | H11: P006 | I11: =_xludf.XLOOKUP(H11,Base_Planos!$A:$A,Base_Planos!$B:$B,"Não encontrado") -> #NAME? | J11: =VLOOKUP(H11,Base_Planos!$A:$G,4,FALSE) -> 119.9 | K11: 45966 | L11: 2025-11 | M11: Ativo | O11: =IF(M11="Cancelado",N11-K11,TODAY()-K11) -> 203 | P11: =IF(O11<=30,"Até 30 dias",IF(O11<=90,"31 a 90 dias",IF(O11<=180,"91 a 180 dias",IF(O11<=365,"181 a 365 dias","Mais de 1 ano")))) -> 181 a 365 dias | Q11: =IF(M11="Cancelado",1,0) -> 0 | R11: 9 | S11: =IF(Q11=1,J11,0) -> 0 | T11: =IF(R11<=6,"Detrator",IF(R11<=8,"Neutro","Promotor")) -> Promotor | U11: =IF(Q11=1,"Alto risco",IF(R11<=6,"Alto risco",IF(R11<=8,"Médio risco","Baixo risco"))) -> Baixo risco | V11: 0 | W11: 82 | X11: 124.03 | Y11: 6 | Z11: Baixo
A12: C0011 | B12: Gustavo Silva | C12: Campinas | D12: SP | E12: 38 | F12: MEI | G12: Instagram | H12: P006 | I12: =_xludf.XLOOKUP(H12,Base_Planos!$A:$A,Base_Planos!$B:$B,"Não encontrado") -> #NAME? | J12: =VLOOKUP(H12,Base_Planos!$A:$G,4,FALSE) -> 119.9 | K12: 45556 | L12: 2024-09 | M12: Cancelado | N12: 46083 | O12: =IF(M12="Cancelado",N12-K12,TODAY()-K12) -> 527 | P12: =IF(O12<=30,"Até 30 dias",IF(O12<=90,"31 a 90 dias",IF(O12<=180,"91 a 180 dias",IF(O12<=365,"181 a 365 dias","Mais de 1 ano")))) -> Mais de 1 ano | Q12: =IF(M12="Cancelado",1,0) -> 1 | R12: 3 | S12: =IF(Q12=1,J12,0) -> 119.9 | T12: =IF(R12<=6,"Detrator",IF(R12<=8,"Neutro","Promotor")) -> Detrator | U12: =IF(Q12=1,"Alto risco",IF(R12<=6,"Alto risco",IF(R12<=8,"Médio risco","Baixo risco"))) -> Alto risco | V12: 3 | W12: 77 | X12: 125.37 | Y12: 17 | Z12: Alto
A13: C0012 | B13: Rafael Pereira | C13: Belo Horizonte | D13: MG | E13: 60 | F13: MEI | G13: Indicação | H13: P002 | I13: =_xludf.XLOOKUP(H13,Base_Planos!$A:$A,Base_Planos!$B:$B,"Não encontrado") -> #NAME? | J13: =VLOOKUP(H13,Base_Planos!$A:$G,4,FALSE) -> 29.9 | K13: 45793 | L13: 2025-05 | M13: Ativo | O13: =IF(M13="Cancelado",N13-K13,TODAY()-K13) -> 376 | P13: =IF(O13<=30,"Até 30 dias",IF(O13<=90,"31 a 90 dias",IF(O13<=180,"91 a 180 dias",IF(O13<=365,"181 a 365 dias","Mais de 1 ano")))) -> Mais de 1 ano | Q13: =IF(M13="Cancelado",1,0) -> 0 | R13: 3 | S13: =IF(Q13=1,J13,0) -> 0 | T13: =IF(R13<=6,"Detrator",IF(R13<=8,"Neutro","Promotor")) -> Detrator | U13: =IF(Q13=1,"Alto risco",IF(R13<=6,"Alto risco",IF(R13<=8,"Médio risco","Baixo risco"))) -> Alto risco | V13: 1 | W13: 36 | X13: 27.8 | Y13: 12 | Z13: Alto
A14: C0013 | B14: Wesley Martins | C14: Fortaleza | D14: CE | E14: 51 | F14: MEI | G14: LinkedIn | H14: P002 | I14: =_xludf.XLOOKUP(H14,Base_Planos!$A:$A,Base_Planos!$B:$B,"Não encontrado") -> #NAME? | J14: =VLOOKUP(H14,Base_Planos!$A:$G,4,FALSE) -> 29.9 | K14: 45619 | L14: 2024-11 | M14: Cancelado | N14: 45709 | O14: =IF(M14="Cancelado",N14-K14,TODAY()-K14) -> 90 | P14: =IF(O14<=30,"Até 30 dias",IF(O14<=90,"31 a 90 dias",IF(O14<=180,"91 a 180 dias",IF(O14<=365,"181 a 365 dias","Mais de 1 ano")))) -> 31 a 90 dias | Q14: =IF(M14="Cancelado",1,0) -> 1 | R14: 0 | S14: =IF(Q14=1,J14,0) -> 29.9 | T14: =IF(R14<=6,"Detrator",IF(R14<=8,"Neutro","Promotor")) -> Detrator | U14: =IF(Q14=1,"Alto risco",IF(R14<=6,"Alto risco",IF(R14<=8,"Médio risco","Baixo risco"))) -> Alto risco | V14: 0 | W14: 46 | X14: 30.83 | Y14: 3 | Z14: Médio
A15: C0014 | B15: Enzo Ribeiro | C15: Rio de Janeiro | D15: RJ | E15: 50 | F15: Pessoa Física | G15: E-mail marketing | H15: P002 | I15: =_xludf.XLOOKUP(H15,Base_Planos!$A:$A,Base_Planos!$B:$B,"Não encontrado") -> #NAME? | J15: =VLOOKUP(H15,Base_Planos!$A:$G,4,FALSE) -> 29.9 | K15: 45197 | L15: 2023-09 | M15: Ativo | O15: =IF(M15="Cancelado",N15-K15,TODAY()-K15) -> 972 | P15: =IF(O15<=30,"Até 30 dias",IF(O15<=90,"31 a 90 dias",IF(O15<=180,"91 a 180 dias",IF(O15<=365,"181 a 365 dias","Mais de 1 ano")))) -> Mais de 1 ano | Q15: =IF(M15="Cancelado",1,0) -> 0 | R15: 9 | S15: =IF(Q15=1,J15,0) -> 0 | T15: =IF(R15<=6,"Detrator",IF(R15<=8,"Neutro","Promotor")) -> Promotor | U15: =IF(Q15=1,"Alto risco",IF(R15<=6,"Alto risco",IF(R15<=8,"Médio risco","Baixo risco"))) -> Baixo risco | V15: 0 | W15: 47 | X15: 25.98 | Y15: 32 | Z15: Baixo
A16: C0015 | B16: Wesley Araújo | C16: Recife | D16: PE | E16: 45 | F16: MEI | G16: Google Ads | H16: P004 | I16: =_xludf.XLOOKUP(H16,Base_Planos!$A:$A,Base_Planos!$B:$B,"Não encontrado") -> #NAME? | J16: =VLOOKUP(H16,Base_Planos!$A:$G,4,FALSE) -> 59.9 | K16: 45128 | L16: 2023-07 | M16: Cancelado | N16: 45352 | O16: =IF(M16="Cancelado",N16-K16,TODAY()-K16) -> 224 | P16: =IF(O16<=30,"Até 30 dias",IF(O16<=90,"31 a 90 dias",IF(O16<=180,"91 a 180 dias",IF(O16<=365,"181 a 365 dias","Mais de 1 ano")))) -> 181 a 365 dias | Q16: =IF(M16="Cancelado",1,0) -> 1 | R16: 0 | S16: =IF(Q16=1,J16,0) -> 59.9 | T16: =IF(R16<=6,"Detrator",IF(R16<=8,"Neutro","Promotor")) -> Detrator | U16: =IF(Q16=1,"Alto risco",IF(R16<=6,"Alto risco",IF(R16<=8,"Médio risco","Baixo risco"))) -> Alto risco | V16: 2 | W16: 71 | X16: 52.59 | Y16: 7 | Z16: Médio
A17: C0016 | B17: Felipe Almeida | C17: Fortaleza | D17: CE | E17: 33 | F17: Média Empresa | G17: Instagram | H17: P003 | I17: =_xludf.XLOOKUP(H17,Base_Planos!$A:$A,Base_Planos!$B:$B,"Não encontrado") -> #NAME? | J17: =VLOOKUP(H17,Base_Planos!$A:$G,4,FALSE) -> 79.9 | K17: 46054 | L17: 2026-02 | M17: Ativo | O17: =IF(M17="Cancelado",N17-K17,TODAY()-K17) -> 115 | P17: =IF(O17<=30,"Até 30 dias",IF(O17<=90,"31 a 90 dias",IF(O17<=180,"91 a 180 dias",IF(O17<=365,"181 a 365 dias","Mais de 1 ano")))) -> 91 a 180 dias | Q17: =IF(M17="Cancelado",1,0) -> 0 | R17: 1 | S17: =IF(Q17=1,J17,0) -> 0 | T17: =IF(R17<=6,"Detrator",IF(R17<=8,"Neutro","Promotor")) -> Detrator | U17: =IF(Q17=1,"Alto risco",IF(R17<=6,"Alto risco",IF(R17<=8,"Médio risco","Baixo risco"))) -> Alto risco | V17: 2 | W17: 90 | X17: 82.72 | Y17: 3 | Z17: Alto
A18: C0017 | B18: Enzo Ferreira | C18: Belo Horizonte | D18: MG | E18: 44 | F18: MEI | G18: LinkedIn | H18: P006 | I18: =_xludf.XLOOKUP(H18,Base_Planos!$A:$A,Base_Planos!$B:$B,"Não encontrado") -> #NAME? | J18: =VLOOKUP(H18,Base_Planos!$A:$G,4,FALSE) -> 119.9 | K18: 45047 | L18: 2023-05 | M18: Ativo | O18: =IF(M18="Cancelado",N18-K18,TODAY()-K18) -> 1122 | P18: =IF(O18<=30,"Até 30 dias",IF(O18<=90,"31 a 90 dias",IF(O18<=180,"91 a 180 dias",IF(O18<=365,"181 a 365 dias","Mais de 1 ano")))) -> Mais de 1 ano | Q18: =IF(M18="Cancelado",1,0) -> 0 | R18: 2 | S18: =IF(Q18=1,J18,0) -> 0 | T18: =IF(R18<=6,"Detrator",IF(R18<=8,"Neutro","Promotor")) -> Detrator | U18: =IF(Q18=1,"Alto risco",IF(R18<=6,"Alto risco",IF(R18<=8,"Médio risco","Baixo risco"))) -> Alto risco | V18: 0 | W18: 100 | X18: 112.83 | Y18: 37 | Z18: Médio
A19: C0018 | B19: Nicolas Dias | C19: Osasco | D19: SP | E19: 63 | F19: MEI | G19: LinkedIn | H19: P002 | I19: =_xludf.XLOOKUP(H19,Base_Planos!$A:$A,Base_Planos!$B:$B,"Não encontrado") -> #NAME? | J19: =VLOOKUP(H19,Base_Planos!$A:$G,4,FALSE) -> 29.9 | K19: 45046 | L19: 2023-04 | M19: Cancelado | N19: 46052 | O19: =IF(M19="Cancelado",N19-K19,TODAY()-K19) -> 1006 | P19: =IF(O19<=30,"Até 30 dias",IF(O19<=90,"31 a 90 dias",IF(O19<=180,"91 a 180 dias",IF(O19<=365,"181 a 365 dias","Mais de 1 ano")))) -> Mais de 1 ano | Q19: =IF(M19="Cancelado",1,0) -> 1 | R19: 9 | S19: =IF(Q19=1,J19,0) -> 29.9 | T19: =IF(R19<=6,"Detrator",IF(R19<=8,"Neutro","Promotor")) -> Promotor | U19: =IF(Q19=1,"Alto risco",IF(R19<=6,"Alto risco",IF(R19<=8,"Médio risco","Baixo risco"))) -> Alto risco | V19: 0 | W19: 47 | X19: 25.76 | Y19: 33 | Z19: Baixo
A20: C0019 | B20: Queila Oliveira | C20: Guarulhos | D20: SP | E20: 29 | F20: Pessoa Física | G20: Instagram | H20: P004 | I20: =_xludf.XLOOKUP(H20,Base_Planos!$A:$A,Base_Planos!$B:$B,"Não encontrado") -> #NAME? | J20: =VLOOKUP(H20,Base_Planos!$A:$G,4,FALSE) -> 59.9 | K20: 45408 | L20: 2024-04 | M20: Ativo | O20: =IF(M20="Cancelado",N20-K20,TODAY()-K20) -> 761 | P20: =IF(O20<=30,"Até 30 dias",IF(O20<=90,"31 a 90 dias",IF(O20<=180,"91 a 180 dias",IF(O20<=365,"181 a 365 dias","Mais de 1 ano")))) -> Mais de 1 ano | Q20: =IF(M20="Cancelado",1,0) -> 0 | R20: 6 | S20: =IF(Q20=1,J20,0) -> 0 | T20: =IF(R20<=6,"Detrator",IF(R20<=8,"Neutro","Promotor")) -> Detrator | U20: =IF(Q20=1,"Alto risco",IF(R20<=6,"Alto risco",IF(R20<=8,"Médio risco","Baixo risco"))) -> Alto risco | V20: 0 | W20: 97 | X20: 58.34 | Y20: 25 | Z20: Médio
A21: C0020 | B21: Nicolas Teixeira | C21: Campinas | D21: SP | E21: 51 | F21: Pessoa Física | G21: Orgânico | H21: P002 | I21: =_xludf.XLOOKUP(H21,Base_Planos!$A:$A,Base_Planos!$B:$B,"Não encontrado") -> #NAME? | J21: =VLOOKUP(H21,Base_Planos!$A:$G,4,FALSE) -> 29.9 | K21: 45570 | L21: 2024-10 | M21: Ativo | O21: =IF(M21="Cancelado",N21-K21,TODAY()-K21) -> 599 | P21: =IF(O21<=30,"Até 30 dias",IF(O21<=90,"31 a 90 dias",IF(O21<=180,"91 a 180 dias",IF(O21<=365,"181 a 365 dias","Mais de 1 ano")))) -> Mais de 1 ano | Q21: =IF(M21="Cancelado",1,0) -> 0 | R21: 3 | S21: =IF(Q21=1,J21,0) -> 0 | T21: =IF(R21<=6,"Detrator",IF(R21<=8,"Neutro","Promotor")) -> Detrator | U21: =IF(Q21=1,"Alto risco",IF(R21<=6,"Alto risco",IF(R21<=8,"Médio risco","Baixo risco"))) -> Alto risco | V21: 1 | W21: 71 | X21: 30.97 | Y21: 19 | Z21: Médio
A22: C0021 | B22: Gustavo Oliveira | C22: São Paulo | D22: SP | E22: 47 | F22: Pequena Empresa | G22: Instagram | H22: P001 | I22: =_xludf.XLOOKUP(H22,Base_Planos!$A:$A,Base_Planos!$B:$B,"Não encontrado") -> #NAME? | J22: =VLOOKUP(H22,Base_Planos!$A:$G,4,FALSE) -> 39.9 | K22: 45363 | L22: 2024-03 | M22: Ativo | O22: =IF(M22="Cancelado",N22-K22,TODAY()-K22) -> 806 | P22: =IF(O22<=30,"Até 30 dias",IF(O22<=90,"31 a 90 dias",IF(O22<=180,"91 a 180 dias",IF(O22<=365,"181 a 365 dias","Mais de 1 ano")))) -> Mais de 1 ano | Q22: =IF(M22="Cancelado",1,0) -> 0 | R22: 8 | S22: =IF(Q22=1,J22,0) -> 0 | T22: =IF(R22<=6,"Detrator",IF(R22<=8,"Neutro","Promotor")) -> Neutro | U22: =IF(Q22=1,"Alto risco",IF(R22<=6,"Alto risco",IF(R22<=8,"Médio risco","Baixo risco"))) -> Médio risco | V22: 2 | W22: 100 | X22: 36.86 | Y22: 26 | Z22: Baixo
A23: C0022 | B23: Felipe Melo | C23: Guarulhos | D23: SP | E23: 52 | F23: Pequena Empresa | G23: Google Ads | H23: P004 | I23: =_xludf.XLOOKUP(H23,Base_Planos!$A:$A,Base_Planos!$B:$B,"Não encontrado") -> #NAME? | J23: =VLOOKUP(H23,Base_Planos!$A:$G,4,FALSE) -> 59.9 | K23: 46062 | L23: 2026-02 | M23: Cancelado | N23: 46105 | O23: =IF(M23="Cancelado",N23-K23,TODAY()-K23) -> 43 | P23: =IF(O23<=30,"Até 30 dias",IF(O23<=90,"31 a 90 dias",IF(O23<=180,"91 a 180 dias",IF(O23<=365,"181 a 365 dias","Mais de 1 ano")))) -> 31 a 90 dias | Q23: =IF(M23="Cancelado",1,0) -> 1 | R23: 4 | S23: =IF(Q23=1,J23,0) -> 59.9 | T23: =IF(R23<=6,"Detrator",IF(R23<=8,"Neutro","Promotor")) -> Detrator | U23: =IF(Q23=1,"Alto risco",IF(R23<=6,"Alto risco",IF(R23<=8,"Médio risco","Baixo risco"))) -> Alto risco | V23: 2 | W23: 51 | X23: 52.78 | Y23: 1 | Z23: Alto
A24: C0023 | B24: João Nascimento | C24: Curitiba | D24: PR | E24: 63 | F24: Pessoa Física | G24: Orgânico | H24: P003 | I24: =_xludf.XLOOKUP(H24,Base_Planos!$A:$A,Base_Planos!$B:$B,"Não encontrado") -> #NAME? | J24: =VLOOKUP(H24,Base_Planos!$A:$G,4,FALSE) -> 79.9 | K24: 45441 | L24: 2024-05 | M24: Cancelado | N24: 45604 | O24: =IF(M24="Cancelado",N24-K24,TODAY()-K24) -> 163 | P24: =IF(O24<=30,"Até 30 dias",IF(O24<=90,"31 a 90 dias",IF(O24<=180,"91 a 180 dias",IF(O24<=365,"181 a 365 dias","Mais de 1 ano")))) -> 91 a 180 dias | Q24: =IF(M24="Cancelado",1,0) -> 1 | R24: 0 | S24: =IF(Q24=1,J24,0) -> 79.9 | T24: =IF(R24<=6,"Detrator",IF(R24<=8,"Neutro","Promotor")) -> Detrator | U24: =IF(Q24=1,"Alto risco",IF(R24<=6,"Alto risco",IF(R24<=8,"Médio risco","Baixo risco"))) -> Alto risco | V24: 0 | W24: 73 | X24: 72.1 | Y24: 5 | Z24: Médio
A25: C0024 | B25: Zeca Melo | C25: Goiânia | D25: GO | E25: 63 | F25: MEI | G25: Google Ads | H25: P001 | I25: =_xludf.XLOOKUP(H25,Base_Planos!$A:$A,Base_Planos!$B:$B,"Não encontrado") -> #NAME? | J25: =VLOOKUP(H25,Base_Planos!$A:$G,4,FALSE) -> 39.9 | K25: 45232 | L25: 2023-11 | M25: Ativo | O25: =IF(M25="Cancelado",N25-K25,TODAY()-K25) -> 937 | P25: =IF(O25<=30,"Até 30 dias",IF(O25<=90,"31 a 90 dias",IF(O25<=180,"91 a 180 dias",IF(O25<=365,"181 a 365 dias","Mais de 1 ano")))) -> Mais de 1 ano | Q25: =IF(M25="Cancelado",1,0) -> 0 | R25: 8 | S25: =IF(Q25=1,J25,0) -> 0 | T25: =IF(R25<=6,"Detrator",IF(R25<=8,"Neutro","Promotor")) -> Neutro | U25: =IF(Q25=1,"Alto risco",IF(R25<=6,"Alto risco",IF(R25<=8,"Médio risco","Baixo risco"))) -> Médio risco | V25: 0 | W25: 63 | X25: 34.25 | Y25: 31 | Z25: Baixo
A26: C0025 | B26: Lucas Santos | C26: Recife | D26: PE | E26: 31 | F26: Pequena Empresa | G26: Instagram | H26: P003 | I26: =_xludf.XLOOKUP(H26,Base_Planos!$A:$A,Base_Planos!$B:$B,"Não encontrado") -> #NAME? | J26: =VLOOKUP(H26,Base_Planos!$A:$G,4,FALSE) -> 79.9 | K26: 46073 | L26: 2026-02 | M26: Cancelado | N26: 46123 | O26: =IF(M26="Cancelado",N26-K26,TODAY()-K26) -> 50 | P26: =IF(O26<=30,"Até 30 dias",IF(O26<=90,"31 a 90 dias",IF(O26<=180,"91 a 180 dias",IF(O26<=365,"181 a 365 dias","Mais de 1 ano")))) -> 31 a 90 dias | Q26: =IF(M26="Cancelado",1,0) -> 1 | R26: 6 | S26: =IF(Q26=1,J26,0) -> 79.9 | T26: =IF(R26<=6,"Detrator",IF(R26<=8,"Neutro","Promotor")) -> Detrator | U26: =IF(Q26=1,"Alto risco",IF(R26<=6,"Alto risco",IF(R26<=8,"Médio risco","Baixo risco"))) -> Alto risco | V26: 3 | W26: 49 | X26: 82 | Y26: 1 | Z26: Alto
A27: C0026 | B27: Ana Lima | C27: Barueri | D27: SP | E27: 39 | F27: Pequena Empresa | G27: Parceiro | H27: P005 | I27: =_xludf.XLOOKUP(H27,Base_Planos!$A:$A,Base_Planos!$B:$B,"Não encontrado") -> #NAME? | J27: =VLOOKUP(H27,Base_Planos!$A:$G,4,FALSE) -> 149.9 | K27: 45435 | L27: 2024-05 | M27: Cancelado | N27: 45946 | O27: =IF(M27="Cancelado",N27-K27,TODAY()-K27) -> 511 | P27: =IF(O27<=30,"Até 30 dias",IF(O27<=90,"31 a 90 dias",IF(O27<=180,"91 a 180 dias",IF(O27<=365,"181 a 365 dias","Mais de 1 ano")))) -> Mais de 1 ano | Q27: =IF(M27="Cancelado",1,0) -> 1 | R27: 4 | S27: =IF(Q27=1,J27,0) -> 149.9 | T27: =IF(R27<=6,"Detrator",IF(R27<=8,"Neutro","Promotor")) -> Detrator | U27: =IF(Q27=1,"Alto risco",IF(R27<=6,"Alto risco",IF(R27<=8,"Médio risco","Baixo risco"))) -> Alto risco | V27: 0 | W27: 93 | X27: 151.9 | Y27: 17 | Z27: Médio
A28: C0027 | B28: Olívia Martins | C28: Porto Alegre | D28: RS | E28: 32 | F28: Pessoa Física | G28: LinkedIn | H28: P003 | I28: =_xludf.XLOOKUP(H28,Base_Planos!$A:$A,Base_Planos!$B:$B,"Não encontrado") -> #NAME? | J28: =VLOOKUP(H28,Base_Planos!$A:$G,4,FALSE) -> 79.9 | K28: 45497 | L28: 2024-07 | M28: Ativo | O28: =IF(M28="Cancelado",N28-K28,TODAY()-K28) -> 672 | P28: =IF(O28<=30,"Até 30 dias",IF(O28<=90,"31 a 90 dias",IF(O28<=180,"91 a 180 dias",IF(O28<=365,"181 a 365 dias","Mais de 1 ano")))) -> Mais de 1 ano | Q28: =IF(M28="Cancelado",1,0) -> 0 | R28: 1 | S28: =IF(Q28=1,J28,0) -> 0 | T28: =IF(R28<=6,"Detrator",IF(R28<=8,"Neutro","Promotor")) -> Detrator | U28: =IF(Q28=1,"Alto risco",IF(R28<=6,"Alto risco",IF(R28<=8,"Médio risco","Baixo risco"))) -> Alto risco | V28: 1 | W28: 52 | X28: 83.59 | Y28: 22 | Z28: Médio
A29: C0028 | B29: Rafael Ribeiro | C29: São Paulo | D29: SP | E29: 25 | F29: Média Empresa | G29: Orgânico | H29: P001 | I29: =_xludf.XLOOKUP(H29,Base_Planos!$A:$A,Base_Planos!$B:$B,"Não encontrado") -> #NAME? | J29: =VLOOKUP(H29,Base_Planos!$A:$G,4,FALSE) -> 39.9 | K29: 45470 | L29: 2024-06 | M29: Cancelado | N29: 46120 | O29: =IF(M29="Cancelado",N29-K29,TODAY()-K29) -> 650 | P29: =IF(O29<=30,"Até 30 dias",IF(O29<=90,"31 a 90 dias",IF(O29<=180,"91 a 180 dias",IF(O29<=365,"181 a 365 dias","Mais de 1 ano")))) -> Mais de 1 ano | Q29: =IF(M29="Cancelado",1,0) -> 1 | R29: 0 | S29: =IF(Q29=1,J29,0) -> 39.9 | T29: =IF(R29<=6,"Detrator",IF(R29<=8,"Neutro","Promotor")) -> Detrator | U29: =IF(Q29=1,"Alto risco",IF(R29<=6,"Alto risco",IF(R29<=8,"Médio risco","Baixo risco"))) -> Alto risco | V29: 1 | W29: 75 | X29: 34.84 | Y29: 21 | Z29: Médio
A30: C0029 | B30: Fernanda Teixeira | C30: Curitiba | D30: PR | E30: 34 | F30: Pessoa Física | G30: Parceiro | H30: P001 | I30: =_xludf.XLOOKUP(H30,Base_Planos!$A:$A,Base_Planos!$B:$B,"Não encontrado") -> #NAME? | J30: =VLOOKUP(H30,Base_Planos!$A:$G,4,FALSE) -> 39.9 | K30: 46029 | L30: 2026-01 | M30: Ativo | O30: =IF(M30="Cancelado",N30-K30,TODAY()-K30) -> 140 | P30: =IF(O30<=30,"Até 30 dias",IF(O30<=90,"31 a 90 dias",IF(O30<=180,"91 a 180 dias",IF(O30<=365,"181 a 365 dias","Mais de 1 ano")))) -> 91 a 180 dias | Q30: =IF(M30="Cancelado",1,0) -> 0 | R30: 10 | S30: =IF(Q30=1,J30,0) -> 0 | T30: =IF(R30<=6,"Detrator",IF(R30<=8,"Neutro","Promotor")) -> Promotor | U30: =IF(Q30=1,"Alto risco",IF(R30<=6,"Alto risco",IF(R30<=8,"Médio risco","Baixo risco"))) -> Baixo risco | V30: 1 | W30: 11 | X30: 34.47 | Y30: 4 | Z30: Médio
A31: C0030 | B31: Wesley Ribeiro | C31: Campinas | D31: SP | E31: 38 | F31: Pequena Empresa | G31: Instagram | H31: P005 | I31: =_xludf.XLOOKUP(H31,Base_Planos!$A:$A,Base_Planos!$B:$B,"Não encontrado") -> #NAME? | J31: =VLOOKUP(H31,Base_Planos!$A:$G,4,FALSE) -> 149.9 | K31: 45542 | L31: 2024-09 | M31: Ativo | O31: =IF(M31="Cancelado",N31-K31,TODAY()-K31) -> 627 | P31: =IF(O31<=30,"Até 30 dias",IF(O31<=90,"31 a 90 dias",IF(O31<=180,"91 a 180 dias",IF(O31<=365,"181 a 365 dias","Mais de 1 ano")))) -> Mais de 1 ano | Q31: =IF(M31="Cancelado",1,0) -> 0 | R31: 8 | S31: =IF(Q31=1,J31,0) -> 0 | T31: =IF(R31<=6,"Detrator",IF(R31<=8,"Neutro","Promotor")) -> Neutro | U31: =IF(Q31=1,"Alto risco",IF(R31<=6,"Alto risco",IF(R31<=8,"Médio risco","Baixo risco"))) -> Médio risco | V31: 0 | W31: 83 | X31: 131.23 | Y31: 20 | Z31: Baixo
A32: C0031 | B32: Nicolas Carvalho | C32: Osasco | D32: SP | E32: 65 | F32: Média Empresa | G32: Orgânico | H32: P003 | I32: =_xludf.XLOOKUP(H32,Base_Planos!$A:$A,Base_Planos!$B:$B,"Não encontrado") -> #NAME? | J32: =VLOOKUP(H32,Base_Planos!$A:$G,4,FALSE) -> 79.9 | K32: 44927 | L32: 2023-01 | M32: Ativo | O32: =IF(M32="Cancelado",N32-K32,TODAY()-K32) -> 1242 | P32: =IF(O32<=30,"Até 30 dias",IF(O32<=90,"31 a 90 dias",IF(O32<=180,"91 a 180 dias",IF(O32<=365,"181 a 365 dias","Mais de 1 ano")))) -> Mais de 1 ano | Q32: =IF(M32="Cancelado",1,0) -> 0 | R32: 4 | S32: =IF(Q32=1,J32,0) -> 0 | T32: =IF(R32<=6,"Detrator",IF(R32<=8,"Neutro","Promotor")) -> Detrator | U32: =IF(Q32=1,"Alto risco",IF(R32<=6,"Alto risco",IF(R32<=8,"Médio risco","Baixo risco"))) -> Alto risco | V32: 0 | W32: 85 | X32: 75.35 | Y32: 41 | Z32: Médio
A33: C0032 | B33: Olívia Costa | C33: Goiânia | D33: GO | E33: 48 | F33: Pequena Empresa | G33: Indicação | H33: P004 | I33: =_xludf.XLOOKUP(H33,Base_Planos!$A:$A,Base_Planos!$B:$B,"Não encontrado") -> #NAME? | J33: =VLOOKUP(H33,Base_Planos!$A:$G,4,FALSE) -> 59.9 | K33: 45508 | L33: 2024-08 | M33: Ativo | O33: =IF(M33="Cancelado",N33-K33,TODAY()-K33) -> 661 | P33: =IF(O33<=30,"Até 30 dias",IF(O33<=90,"31 a 90 dias",IF(O33<=180,"91 a 180 dias",IF(O33<=365,"181 a 365 dias","Mais de 1 ano")))) -> Mais de 1 ano | Q33: =IF(M33="Cancelado",1,0) -> 0 | R33: 8 | S33: =IF(Q33=1,J33,0) -> 0 | T33: =IF(R33<=6,"Detrator",IF(R33<=8,"Neutro","Promotor")) -> Neutro | U33: =IF(Q33=1,"Alto risco",IF(R33<=6,"Alto risco",IF(R33<=8,"Médio risco","Baixo risco"))) -> Médio risco | V33: 0 | W33: 23 | X33: 53.73 | Y33: 22 | Z33: Baixo
A34: C0033 | B34: João Ferreira | C34: Santo André | D34: SP | E34: 30 | F34: Pessoa Física | G34: Google Ads | H34: P002 | I34: =_xludf.XLOOKUP(H34,Base_Planos!$A:$A,Base_Planos!$B:$B,"Não encontrado") -> #NAME? | J34: =VLOOKUP(H34,Base_Planos!$A:$G,4,FALSE) -> 29.9 | K34: 45900 | L34: 2025-08 | M34: Ativo | O34: =IF(M34="Cancelado",N34-K34,TODAY()-K34) -> 269 | P34: =IF(O34<=30,"Até 30 dias",IF(O34<=90,"31 a 90 dias",IF(O34<=180,"91 a 180 dias",IF(O34<=365,"181 a 365 dias","Mais de 1 ano")))) -> 181 a 365 dias | Q34: =IF(M34="Cancelado",1,0) -> 0 | R34: 9 | S34: =IF(Q34=1,J34,0) -> 0 | T34: =IF(R34<=6,"Detrator",IF(R34<=8,"Neutro","Promotor")) -> Promotor | U34: =IF(Q34=1,"Alto risco",IF(R34<=6,"Alto risco",IF(R34<=8,"Médio risco","Baixo risco"))) -> Baixo risco | V34: 0 | W34: 48 | X34: 26.58 | Y34: 8 | Z34: Baixo
A35: C0034 | B35: Yasmin Carvalho | C35: Fortaleza | D35: CE | E35: 43 | F35: Pessoa Física | G35: Google Ads | H35: P006 | I35: =_xludf.XLOOKUP(H35,Base_Planos!$A:$A,Base_Planos!$B:$B,"Não encontrado") -> #NAME? | J35: =VLOOKUP(H35,Base_Planos!$A:$G,4,FALSE) -> 119.9 | K35: 45145 | L35: 2023-08 | M35: Ativo | O35: =IF(M35="Cancelado",N35-K35,TODAY()-K35) -> 1024 | P35: =IF(O35<=30,"Até 30 dias",IF(O35<=90,"31 a 90 dias",IF(O35<=180,"91 a 180 dias",IF(O35<=365,"181 a 365 dias","Mais de 1 ano")))) -> Mais de 1 ano | Q35: =IF(M35="Cancelado",1,0) -> 0 | R35: 6 | S35: =IF(Q35=1,J35,0) -> 0 | T35: =IF(R35<=6,"Detrator",IF(R35<=8,"Neutro","Promotor")) -> Detrator | U35: =IF(Q35=1,"Alto risco",IF(R35<=6,"Alto risco",IF(R35<=8,"Médio risco","Baixo risco"))) -> Alto risco | V35: 1 | W35: 100 | X35: 115.28 | Y35: 34 | Z35: Médio
A36: C0035 | B36: Gustavo Souza | C36: Fortaleza | D36: CE | E36: 26 | F36: Pequena Empresa | G36: YouTube | H36: P007 | I36: =_xludf.XLOOKUP(H36,Base_Planos!$A:$A,Base_Planos!$B:$B,"Não encontrado") -> #NAME? | J36: =VLOOKUP(H36,Base_Planos!$A:$G,4,FALSE) -> 399.9 | K36: 45833 | L36: 2025-06 | M36: Ativo | O36: =IF(M36="Cancelado",N36-K36,TODAY()-K36) -> 336 | P36: =IF(O36<=30,"Até 30 dias",IF(O36<=90,"31 a 90 dias",IF(O36<=180,"91 a 180 dias",IF(O36<=365,"181 a 365 dias","Mais de 1 ano")))) -> 181 a 365 dias | Q36: =IF(M36="Cancelado",1,0) -> 0 | R36: 9 | S36: =IF(Q36=1,J36,0) -> 0 | T36: =IF(R36<=6,"Detrator",IF(R36<=8,"Neutro","Promotor")) -> Promotor | U36: =IF(Q36=1,"Alto risco",IF(R36<=6,"Alto risco",IF(R36<=8,"Médio risco","Baixo risco"))) -> Baixo risco | V36: 0 | W36: 2 | X36: 375.58 | Y36: 11 | Z36: Médio
A37: C0036 | B37: Felipe Barbosa | C37: Fortaleza | D37: CE | E37: 34 | F37: Pequena Empresa | G37: Orgânico | H37: P005 | I37: =_xludf.XLOOKUP(H37,Base_Planos!$A:$A,Base_Planos!$B:$B,"Não encontrado") -> #NAME? | J37: =VLOOKUP(H37,Base_Planos!$A:$G,4,FALSE) -> 149.9 | K37: 45994 | L37: 2025-12 | M37: Ativo | O37: =IF(M37="Cancelado",N37-K37,TODAY()-K37) -> 175 | P37: =IF(O37<=30,"Até 30 dias",IF(O37<=90,"31 a 90 dias",IF(O37<=180,"91 a 180 dias",IF(O37<=365,"181 a 365 dias","Mais de 1 ano")))) -> 91 a 180 dias | Q37: =IF(M37="Cancelado",1,0) -> 0 | R37: 7 | S37: =IF(Q37=1,J37,0) -> 0 | T37: =IF(R37<=6,"Detrator",IF(R37<=8,"Neutro","Promotor")) -> Neutro | U37: =IF(Q37=1,"Alto risco",IF(R37<=6,"Alto risco",IF(R37<=8,"Médio risco","Baixo risco"))) -> Médio risco | V37: 0 | W37: 40 | X37: 135.56 | Y37: 5 | Z37: Baixo
A38: C0037 | B38: Karina Dias | C38: Rio de Janeiro | D38: RJ | E38: 26 | F38: Pessoa Física | G38: Parceiro | H38: P004 | I38: =_xludf.XLOOKUP(H38,Base_Planos!$A:$A,Base_Planos!$B:$B,"Não encontrado") -> #NAME? | J38: =VLOOKUP(H38,Base_Planos!$A:$G,4,FALSE) -> 59.9 | K38: 45365 | L38: 2024-03 | M38: Cancelado | N38: 45825 | O38: =IF(M38="Cancelado",N38-K38,TODAY()-K38) -> 460 | P38: =IF(O38<=30,"Até 30 dias",IF(O38<=90,"31 a 90 dias",IF(O38<=180,"91 a 180 dias",IF(O38<=365,"181 a 365 dias","Mais de 1 ano")))) -> Mais de 1 ano | Q38: =IF(M38="Cancelado",1,0) -> 1 | R38: 1 | S38: =IF(Q38=1,J38,0) -> 59.9 | T38: =IF(R38<=6,"Detrator",IF(R38<=8,"Neutro","Promotor")) -> Detrator | U38: =IF(Q38=1,"Alto risco",IF(R38<=6,"Alto risco",IF(R38<=8,"Médio risco","Baixo risco"))) -> Alto risco | V38: 0 | W38: 69 | X38: 60.14 | Y38: 15 | Z38: Médio
A39: C0038 | B39: Yasmin Silva | C39: Guarulhos | D39: SP | E39: 54 | F39: MEI | G39: Google Ads | H39: P007 | I39: =_xludf.XLOOKUP(H39,Base_Planos!$A:$A,Base_Planos!$B:$B,"Não encontrado") -> #NAME? | J39: =VLOOKUP(H39,Base_Planos!$A:$G,4,FALSE) -> 399.9 | K39: 45538 | L39: 2024-09 | M39: Ativo | O39: =IF(M39="Cancelado",N39-K39,TODAY()-K39) -> 631 | P39: =IF(O39<=30,"Até 30 dias",IF(O39<=90,"31 a 90 dias",IF(O39<=180,"91 a 180 dias",IF(O39<=365,"181 a 365 dias","Mais de 1 ano")))) -> Mais de 1 ano | Q39: =IF(M39="Cancelado",1,0) -> 0 | R39: 6 | S39: =IF(Q39=1,J39,0) -> 0 | T39: =IF(R39<=6,"Detrator",IF(R39<=8,"Neutro","Promotor")) -> Detrator | U39: =IF(Q39=1,"Alto risco",IF(R39<=6,"Alto risco",IF(R39<=8,"Médio risco","Baixo risco"))) -> Alto risco | V39: 0 | W39: 1 | X39: 383.59 | Y39: 21 | Z39: Alto
A40: C0039 | B40: Thiago Ferreira | C40: Fortaleza | D40: CE | E40: 32 | F40: Pessoa Física | G40: E-mail marketing | H40: P001 | I40: =_xludf.XLOOKUP(H40,Base_Planos!$A:$A,Base_Planos!$B:$B,"Não encontrado") -> #NAME? | J40: =VLOOKUP(H40,Base_Planos!$A:$G,4,FALSE) -> 39.9 | K40: 45615 | L40: 2024-11 | M40: Ativo | O40: =IF(M40="Cancelado",N40-K40,TODAY()-K40) -> 554 | P40: =IF(O40<=30,"Até 30 dias",IF(O40<=90,"31 a 90 dias",IF(O40<=180,"91 a 180 dias",IF(O40<=365,"181 a 365 dias","Mais de 1 ano")))) -> Mais de 1 ano | Q40: =IF(M40="Cancelado",1,0) -> 0 | R40: 10 | S40: =IF(Q40=1,J40,0) -> 0 | T40: =IF(R40<=6,"Detrator",IF(R40<=8,"Neutro","Promotor")) -> Promotor | U40: =IF(Q40=1,"Alto risco",IF(R40<=6,"Alto risco",IF(R40<=8,"Médio risco","Baixo risco"))) -> Baixo risco | V40: 0 | W40: 31 | X40: 34.93 | Y40: 18 | Z40: Baixo
...

Sheet Base_Planos
A1: Plano_ID | B1: Nome_Plano | C1: Categoria | D1: Valor_Plano | E1: Limite_Usuarios | F1: Suporte | G1: Contrato_Meses
A2: P001 | B2: Basic Mensal | C2: Entrada | D2: 39.9 | E2: 1 | F2: E-mail | G2: 1
A3: P002 | B3: Basic Anual | C3: Entrada | D3: 29.9 | E3: 1 | F3: E-mail | G3: 12
A4: P003 | B4: Plus Mensal | C4: Intermediário | D4: 79.9 | E4: 3 | F4: Chat | G4: 1
A5: P004 | B5: Plus Anual | C5: Intermediário | D5: 59.9 | E5: 3 | F5: Chat | G5: 12
A6: P005 | B6: Premium Mensal | C6: Avançado | D6: 149.9 | E6: 10 | F6: Prioritário | G6: 1
A7: P006 | B7: Premium Anual | C7: Avançado | D7: 119.9 | E7: 10 | F7: Prioritário | G7: 12
A8: P007 | B8: Enterprise | C8: Corporativo | D8: 399.9 | E8: 50 | F8: Gerente de conta | G8: 12

Sheet Base_Interacoes
A1: ID_Interacao | B1: ID_Cliente | C1: Data_Interacao | D1: Tipo_Contato | E1: Canal_Atendimento | F1: Tempo_Resposta_Horas | G1: Resolvido | H1: Satisfacao_Pos_Atendimento
A2: I00001 | B2: C0470 | C2: 45091 | D2: Reclamação | E2: Chat | F2: 1.1 | G2: Não | H2: 3
A3: I00002 | B3: C0011 | C3: 46101 | D3: Dúvida | E3: WhatsApp | F3: 1.8 | G3: Sim | H3: 4
A4: I00003 | B4: C0037 | C4: 45480 | D4: Financeiro | E4: Telefone | F4: 3.7 | G4: Sim | H4: 4
A5: I00004 | B5: C0417 | C5: 45627 | D5: Dúvida | E5: Telefone | F5: 10.2 | G5: Sim | H5: 4
A6: I00005 | B6: C0289 | C6: 45473 | D6: Dúvida | E6: WhatsApp | F6: 20.1 | G6: Sim | H6: 3
A7: I00006 | B7: C0883 | C7: 45969 | D7: Downgrade | E7: Chat | F7: 13.3 | G7: Sim | H7: 1
A8: I00007 | B8: C0249 | C8: 45079 | D8: Dúvida | E8: Chat | F8: 1.3 | G8: Sim | H8: 1
A9: I00008 | B9: C0885 | C9: 45081 | D9: Dúvida | E9: Chat | F9: 10.7 | G9: Sim | H9: 5
A10: I00009 | B10: C0073 | C10: 45246 | D10: Problema técnico | E10: WhatsApp | F10: 8 | G10: Sim | H10: 1
A11: I00010 | B11: C0628 | C11: 45176 | D11: Dúvida | E11: E-mail | F11: 1.8 | G11: Sim | H11: 1
A12: I00011 | B12: C0191 | C12: 45114 | D12: Financeiro | E12: Chat | F12: 0.2 | G12: Sim | H12: 2
A13: I00012 | B13: C0216 | C13: 45029 | D13: Financeiro | E13: WhatsApp | F13: 3.1 | G13: Sim | H13: 4
... A2001: I02000 | B2001: C0066 | C2001: 45016 | D2001: Downgrade | E2001: Chat | F2001: 3.8 | G2001: Não | H2001: 1

Sheet Base_Cancelamentos
A1: ID_Cancelamento | B1: ID_Cliente | C1: Data_Cancelamento | D1: Motivo_Cancelamento | E1: Mes_Cancelamento | F1: Canal_Aquisicao_PROCX | G1: Plano_PROCX | H1: Tempo_Cliente_Meses_PROCV
A2: CAN0001 | B2: C0001 | C2: 45261 | D2: Migrou para concorrente | E2: 2023-12 | F2: =_xludf.XLOOKUP(B2,Base_Clientes!$A:$A,Base_Clientes!$G:$G,"Não encontrado") -> #NAME? | G2: =_xludf.XLOOKUP(B2,Base_Clientes!$A:$A,Base_Clientes!$I:$I,"Não encontrado") -> #NAME? | H2: =VLOOKUP(B2,Base_Clientes!$A:$Z,21,FALSE) -> Alto risco
A3: CAN0002 | B3: C0003 | C3: 46133 | D3: Cancelamento financeiro | E3: 2026-04 | F3: =_xludf.XLOOKUP(B3,Base_Clientes!$A:$A,Base_Clientes!$G:$G,"Não encontrado") -> #NAME? | G3: =_xludf.XLOOKUP(B3,Base_Clientes!$A:$A,Base_Clientes!$I:$I,"Não encontrado") -> #NAME? | H3: =VLOOKUP(B3,Base_Clientes!$A:$Z,21,FALSE) -> Alto risco
A4: CAN0003 | B4: C0004 | C4: 45887 | D4: Produto não atende | E4: 2025-08 | F4: =_xludf.XLOOKUP(B4,Base_Clientes!$A:$A,Base_Clientes!$G:$G,"Não encontrado") -> #NAME? | G4: =_xludf.XLOOKUP(B4,Base_Clientes!$A:$A,Base_Clientes!$I:$I,"Não encontrado") -> #NAME? | H4: =VLOOKUP(B4,Base_Clientes!$A:$Z,21,FALSE) -> Alto risco
A5: CAN0004 | B5: C0011 | C5: 46083 | D5: Problemas técnicos | E5: 2026-03 | F5: =_xludf.XLOOKUP(B5,Base_Clientes!$A:$A,Base_Clientes!$G:$G,"Não encontrado") -> #NAME? | G5: =_xludf.XLOOKUP(B5,Base_Clientes!$A:$A,Base_Clientes!$I:$I,"Não encontrado") -> #NAME? | H5: =VLOOKUP(B5,Base_Clientes!$A:$Z,21,FALSE) -> Alto risco
A6: CAN0005 | B6: C0013 | C6: 45709 | D6: Suporte insatisfatório | E6: 2025-02 | F6: =_xludf.XLOOKUP(B6,Base_Clientes!$A:$A,Base_Clientes!$G:$G,"Não encontrado") -> #NAME? | G6: =_xludf.XLOOKUP(B6,Base_Clientes!$A:$A,Base_Clientes!$I:$I,"Não encontrado") -> #NAME? | H6: =VLOOKUP(B6,Base_Clientes!$A:$Z,21,FALSE) -> Alto risco
A7: CAN0006 | B7: C0015 | C7: 45352 | D7: Migrou para concorrente | E7: 2024-03 | F7: =_xludf.XLOOKUP(B7,Base_Clientes!$A:$A,Base_Clientes!$G:$G,"Não encontrado") -> #NAME? | G7: =_xludf.XLOOKUP(B7,Base_Clientes!$A:$A,Base_Clientes!$I:$I,"Não encontrado") -> #NAME? | H7: =VLOOKUP(B7,Base_Clientes!$A:$Z,21,FALSE) -> Alto risco
A8: CAN0007 | B8: C0018 | C8: 46052 | D8: Suporte insatisfatório | E8: 2026-01 | F8: =_xludf.XLOOKUP(B8,Base_Clientes!$A:$A,Base_Clientes!$G:$G,"Não encontrado") -> #NAME? | G8: =_xludf.XLOOKUP(B8,Base_Clientes!$A:$A,Base_Clientes!$I:$I,"Não encontrado") -> #NAME? | H8: =VLOOKUP(B8,Base_Clientes!$A:$Z,21,FALSE) -> Alto risco
A9: CAN0008 | B9: C0022 | C9: 46105 | D9: Produto não atende | E9: 2026-03 | F9: =_xludf.XLOOKUP(B9,Base_Clientes!$A:$A,Base_Clientes!$G:$G,"Não encontrado") -> #NAME? | G9: =_xludf.XLOOKUP(B9,Base_Clientes!$A:$A,Base_Clientes!$I:$I,"Não encontrado") -> #NAME? | H9: =VLOOKUP(B9,Base_Clientes!$A:$Z,21,FALSE) -> Alto risco
A10: CAN0009 | B10: C0023 | C10: 45604 | D10: Produto não atende | E10: 2024-11 | F10: =_xludf.XLOOKUP(B10,Base_Clientes!$A:$A,Base_Clientes!$G:$G,"Não encontrado") -> #NAME? | G10: =_xludf.XLOOKUP(B10,Base_Clientes!$A:$A,Base_Clientes!$I:$I,"Não encontrado") -> #NAME? | H10: =VLOOKUP(B10,Base_Clientes!$A:$Z,21,FALSE) -> Alto risco
A11: CAN0010 | B11: C0025 | C11: 46123 | D11: Suporte insatisfatório | E11: 2026-04 | F11: =_xludf.XLOOKUP(B11,Base_Clientes!$A:$A,Base_Clientes!$G:$G,"Não encontrado") -> #NAME? | G11: =_xludf.XLOOKUP(B11,Base_Clientes!$A:$A,Base_Clientes!$I:$I,"Não encontrado") -> #NAME? | H11: =VLOOKUP(B11,Base_Clientes!$A:$Z,21,FALSE) -> Alto risco
A12: CAN0011 | B12: C0026 | C12: 45946 | D12: Suporte insatisfatório | E12: 2025-10 | F12: =_xludf.XLOOKUP(B12,Base_Clientes!$A:$A,Base_Clientes!$G:$G,"Não encontrado") -> #NAME? | G12: =_xludf.XLOOKUP(B12,Base_Clientes!$A:$A,Base_Clientes!$I:$I,"Não encontrado") -> #NAME? | H12: =VLOOKUP(B12,Base_Clientes!$A:$Z,21,FALSE) -> Alto risco
A13: CAN0012 | B13: C0028 | C13: 46120 | D13: Contrato encerrado | E13: 2026-04 | F13: =_xludf.XLOOKUP(B13,Base_Clientes!$A:$A,Base_Clientes!$G:$G,"Não encontrado") -> #NAME? | G13: =_xludf.XLOOKUP(B13,Base_Clientes!$A:$A,Base_Clientes!$I:$I,"Não encontrado") -> #NAME? | H13: =VLOOKUP(B13,Base_Clientes!$A:$Z,21,FALSE) -> Alto risco
... A293: CAN0292 | B293: C0999 | C293: 46034 | D293: Pouco uso | E293: 2026-01 | F293: =_xludf.XLOOKUP(B293,Base_Clientes!$A:$A,Base_Clientes!$G:$G,"Não encontrado") -> #NAME? | G293: =_xludf.XLOOKUP(B293,Base_Clientes!$A:$A,Base_Clientes!$I:$I,"Não encontrado") -> #NAME? | H293: =VLOOKUP(B293,Base_Clientes!$A:$Z,21,FALSE) -> Alto risco

Sheet Consultas_PROCV_PROCX
A1: Exercícios de PROCX e PROCV para análise de cancelamento de clientes
A3: Digite um ID_Cliente aqui: | B3: C0001
A5: Campo buscado | B5: Resultado
A6: Nome do cliente | B6: =_xlfn.XLOOKUP($B$3,Base_Clientes!$A:$A,Base_Clientes!$B:$B,"Não encontrado") -> Valentina Souza
A7: Status | B7: =_xlfn.XLOOKUP($B$3,Base_Clientes!$A:$A,Base_Clientes!$H:$H,"Não encontrado") -> P001
A8: Plano | B8: =_xlfn.XLOOKUP(B7,Base_Planos!A:A,Base_Planos!B:B,"Não encontrado") -> Basic Mensal
A9: Valor do plano | B9: =VLOOKUP($B$3,Base_Clientes!$A:$Z,10,FALSE) -> 39.9
A10: Motivo de cancelamento | B10: =_xlfn.XLOOKUP($B$3,Base_Clientes!$A:$A,Base_Clientes!$W:$W,"Não encontrado") -> 21
A11: Risco de churn | B11: =_xlfn.XLOOKUP($B$3,Base_Clientes!$A:$A,Base_Clientes!$Z:$Z,"Não encontrado") -> Médio
A13: Fórmulas em português para você treinar no Excel BR
A14: Objetivo | B14: Fórmula em inglês no arquivo | C14: Como ficaria em PT-BR
A15: Buscar nome pelo ID | B15: =XLOOKUP($B$3,Base_Clientes!$A:$A,Base_Clientes!$B:$B,"Não encontrado") | C15: =PROCX($B$3;Base_Clientes!$A:$A;Base_Clientes!$B:$B;"Não encontrado")
A16: Buscar status pelo ID | B16: =XLOOKUP($B$3,Base_Clientes!$A:$A,Base_Clientes!$M:$M,"Não encontrado") | C16: =PROCX($B$3;Base_Clientes!$A:$A;Base_Clientes!$M:$M;"Não encontrado")
A17: Buscar valor do plano | B17: =VLOOKUP($B$3,Base_Clientes!$A:$V,10,FALSE) | C17: =PROCV($B$3;Base_Clientes!$A:$V;10;FALSO)
A18: Buscar plano pelo Plano_ID | B18: =XLOOKUP(H2,Base_Planos!$A:$A,Base_Planos!$B:$B,"Não encontrado") | C18: =PROCX(H2;Base_Planos!$A:$A;Base_Planos!$B:$B;"Não encontrado")
A19: Buscar tempo de cliente | B19: =VLOOKUP(B2,Base_Clientes!$A:$V,21,FALSE) | C19: =PROCV(B2;Base_Clientes!$A:$V;21;FALSO)

Sheet Resumo
A1: Resumo do Projeto — Análise de Cancelamento de Clientes (Churn)
A3: Indicador | B3: Resultado | D3: Perguntas para responder no dashboard
A4: Total de clientes | B4: =COUNTA(Base_Clientes!$A$2:$A$1001) -> 1000 | D4: 1 | E4: Quais planos têm maior taxa de cancelamento?
A5: Clientes ativos | B5: =COUNTIF(Base_Clientes!$M$2:$M$1001,"Ativo") -> 708 | D5: 2 | E5: Quais motivos mais aparecem nos cancelamentos?
A6: Clientes cancelados | B6: =COUNTIF(Base_Clientes!$M$2:$M$1001,"Cancelado") -> 292 | D6: 3 | E6: Clientes com baixo uso cancelam mais?
A7: Taxa de churn | B7: =B6/B4 -> 0.292 | D7: 4 | E7: O NPS tem relação com o churn?
A8: Ticket médio | B8: =AVERAGE(Base_Clientes!$X$2:$X$1001) -> 87.45321 | D8: 5 | E8: Qual canal de aquisição traz clientes com maior permanência?
A9: NPS médio | B9: =AVERAGE(Base_Clientes!$R$2:$R$1001) -> 5.106 | D9: 6 | E9: Qual segmento tem maior risco de churn?
A10: Uso médio 30d | B10: =AVERAGE(Base_Clientes!$W$2:$W$1001) -> 54.424 | D10: 7 | E10: Quanto de receita mensal foi perdida com cancelamentos?
